<?xml version="1.0" encoding="utf-8" ?>
<!-- =================================================================================== -->
<!-- |    This document was autogenerated by xacro from /home/sjtu/UR5_ws/src/ur_gripper_sjtu/ur_gripper_description/urdf/ur_gripper.urdf.xacro | -->
<!-- |    EDITING THIS FILE BY HAND IS NOT RECOMMENDED                                 | -->
<!-- =================================================================================== -->
<robot name="ur_gripper_robot" xmlns:controller="http://playerstage.sourceforge.net/gazebo/xmlschema/#controller" xmlns:interface="http://playerstage.sourceforge.net/gazebo/xmlschema/#interface" xmlns:sensor="http://playerstage.sourceforge.net/gazebo/xmlschema/#sensor">
    <!-- common stuff -->
    <gazebo>
        <plugin filename="libgazebo_ros_control.so" name="gazebo_ros_control" />
    </gazebo>
    <!-- measured from model -->
    <!--property name="shoulder_height" value="0.089159" /-->
    <!--property name="shoulder_offset" value="0.13585" /-->
    <!-- shoulder_offset - elbow_offset + wrist_1_length = 0.10915 -->
    <!--property name="upper_arm_length" value="0.42500" /-->
    <!--property name="elbow_offset" value="0.1197" /-->
    <!-- CAD measured -->
    <!--property name="forearm_length" value="0.39225" /-->
    <!--property name="wrist_1_length" value="0.093" /-->
    <!-- CAD measured -->
    <!--property name="wrist_2_length" value="0.09465" /-->
    <!-- In CAD this distance is 0.930, but in the spec it is 0.09465 -->
    <!--property name="wrist_3_length" value="0.0823" /-->
    <!-- manually measured -->
    <link name="base_link">
        <visual>
            <geometry>
                <mesh filename="package://ur_description/meshes/ur5/visual/base.dae" />
            </geometry>
            <material name="LightGrey">
                <color rgba="0.7 0.7 0.7 1.0" />
            </material>
        </visual>
        <collision>
            <geometry>
                <mesh filename="package://ur_description/meshes/ur5/collision/base.stl" />
            </geometry>
        </collision>
        
<inertial>
            <mass value="4.0" />
            <origin rpy="0 0 0" xyz="0.0 0.0 0.0" />
            <inertia ixx="0.00443333156" ixy="0.0" ixz="0.0" iyy="0.00443333156" iyz="0.0" izz="0.0072" />
        </inertial>

    </link>
    <joint name="shoulder_pan_joint" type="revolute">
        <parent link="base_link" />
        <child link="shoulder_link" />
        <origin rpy="0.0 0.0 0.0" xyz="0.0 0.0 0.089159" />
        <axis xyz="0 0 1" />
        <limit effort="150.0" lower="-6.28318530718" upper="6.28318530718" velocity="3.15" />
        <dynamics damping="0.0" friction="0.0" />
    </joint>
    <link name="shoulder_link">
        <visual>
            <geometry>
                <mesh filename="package://ur_description/meshes/ur5/visual/shoulder.dae" />
            </geometry>
            <material name="LightGrey">
                <color rgba="0.7 0.7 0.7 1.0" />
            </material>
        </visual>
        <collision>
            <geometry>
                <mesh filename="package://ur_description/meshes/ur5/collision/shoulder.stl" />
            </geometry>
        </collision>
        
<inertial>
            <mass value="3.7" />
            <origin rpy="0 0 0" xyz="0.0 0.0 0.0" />
            <inertia ixx="0.010267495893" ixy="0.0" ixz="0.0" iyy="0.010267495893" iyz="0.0" izz="0.00666" />
        </inertial>

    </link>
    <joint name="shoulder_lift_joint" type="revolute">
        <parent link="shoulder_link" />
        <child link="upper_arm_link" />
        <origin rpy="0.0 1.57079632679 0.0" xyz="0.0 0.13585 0.0" />
        <axis xyz="0 1 0" />
        <limit effort="150.0" lower="-6.28318530718" upper="6.28318530718" velocity="3.15" />
        <dynamics damping="0.0" friction="0.0" />
    </joint>
    <link name="upper_arm_link">
        <visual>
            <geometry>
                <mesh filename="package://ur_description/meshes/ur5/visual/upperarm.dae" />
            </geometry>
            <material name="LightGrey">
                <color rgba="0.7 0.7 0.7 1.0" />
            </material>
        </visual>
        <collision>
            <geometry>
                <mesh filename="package://ur_description/meshes/ur5/collision/upperarm.stl" />
            </geometry>
        </collision>
        
<inertial>
            <mass value="8.393" />
            <origin rpy="0 0 0" xyz="0.0 0.0 0.28" />
            <inertia ixx="0.22689067591" ixy="0.0" ixz="0.0" iyy="0.22689067591" iyz="0.0" izz="0.0151074" />
        </inertial>

    </link>
    <joint name="elbow_joint" type="revolute">
        <parent link="upper_arm_link" />
        <child link="forearm_link" />
        <origin rpy="0.0 0.0 0.0" xyz="0.0 -0.1197 0.425" />
        <axis xyz="0 1 0" />
        <limit effort="150.0" lower="-3.14159265359" upper="3.14159265359" velocity="3.15" />
        <dynamics damping="0.0" friction="0.0" />
    </joint>
    <link name="forearm_link">
        <visual>
            <geometry>
                <mesh filename="package://ur_description/meshes/ur5/visual/forearm.dae" />
            </geometry>
            <material name="LightGrey">
                <color rgba="0.7 0.7 0.7 1.0" />
            </material>
        </visual>
        <collision>
            <geometry>
                <mesh filename="package://ur_description/meshes/ur5/collision/forearm.stl" />
            </geometry>
        </collision>
        
<inertial>
            <mass value="2.275" />
            <origin rpy="0 0 0" xyz="0.0 0.0 0.196125" />
            <inertia ixx="0.0312167910289" ixy="0.0" ixz="0.0" iyy="0.0312167910289" iyz="0.0" izz="0.004095" />
        </inertial>

    </link>
    <joint name="wrist_1_joint" type="revolute">
        <parent link="forearm_link" />
        <child link="wrist_1_link" />
        <origin rpy="0.0 1.57079632679 0.0" xyz="0.0 0.0 0.39225" />
        <axis xyz="0 1 0" />
        <limit effort="28.0" lower="-6.28318530718" upper="6.28318530718" velocity="3.2" />
        <dynamics damping="0.0" friction="0.0" />
    </joint>
    <link name="wrist_1_link">
        <visual>
            <geometry>
                <mesh filename="package://ur_description/meshes/ur5/visual/wrist1.dae" />
            </geometry>
            <material name="LightGrey">
                <color rgba="0.7 0.7 0.7 1.0" />
            </material>
        </visual>
        <collision>
            <geometry>
                <mesh filename="package://ur_description/meshes/ur5/collision/wrist1.stl" />
            </geometry>
        </collision>
        
<inertial>
            <mass value="1.219" />
            <origin rpy="0 0 0" xyz="0.0 0.093 0.0" />
            <inertia ixx="0.00255989897604" ixy="0.0" ixz="0.0" iyy="0.00255989897604" iyz="0.0" izz="0.0021942" />
        </inertial>

    </link>
    <joint name="wrist_2_joint" type="revolute">
        <parent link="wrist_1_link" />
        <child link="wrist_2_link" />
        <origin rpy="0.0 0.0 0.0" xyz="0.0 0.093 0.0" />
        <axis xyz="0 0 1" />
        <limit effort="28.0" lower="-6.28318530718" upper="6.28318530718" velocity="3.2" />
        <dynamics damping="0.0" friction="0.0" />
    </joint>
    <link name="wrist_2_link">
        <visual>
            <geometry>
                <mesh filename="package://ur_description/meshes/ur5/visual/wrist2.dae" />
            </geometry>
            <material name="LightGrey">
                <color rgba="0.7 0.7 0.7 1.0" />
            </material>
        </visual>
        <collision>
            <geometry>
                <mesh filename="package://ur_description/meshes/ur5/collision/wrist2.stl" />
            </geometry>
        </collision>
        
<inertial>
            <mass value="1.219" />
            <origin rpy="0 0 0" xyz="0.0 0.0 0.09465" />
            <inertia ixx="0.00255989897604" ixy="0.0" ixz="0.0" iyy="0.00255989897604" iyz="0.0" izz="0.0021942" />
        </inertial>

    </link>
    <joint name="wrist_3_joint" type="revolute">
        <parent link="wrist_2_link" />
        <child link="wrist_3_link" />
        <origin rpy="0.0 0.0 0.0" xyz="0.0 0.0 0.09465" />
        <axis xyz="0 1 0" />
        <limit effort="28.0" lower="-6.28318530718" upper="6.28318530718" velocity="3.2" />
        <dynamics damping="0.0" friction="0.0" />
    </joint>
    <link name="wrist_3_link">
        <visual>
            <geometry>
                <mesh filename="package://ur_description/meshes/ur5/visual/wrist3.dae" />
            </geometry>
            <material name="LightGrey">
                <color rgba="0.7 0.7 0.7 1.0" />
            </material>
        </visual>
        <collision>
            <geometry>
                <mesh filename="package://ur_description/meshes/ur5/collision/wrist3.stl" />
            </geometry>
        </collision>
        
<inertial>
            <mass value="0.1879" />
            <origin rpy="1.57079632679 0 0" xyz="0.0 0.06505 0.0" />
            <inertia ixx="8.46958911216e-05" ixy="0.0" ixz="0.0" iyy="8.46958911216e-05" iyz="0.0" izz="0.0001321171875" />
        </inertial>

    </link>
    <joint name="ee_fixed_joint" type="fixed">
        <parent link="wrist_3_link" />
        <child link="ee_link" />
        <origin rpy="0.0 0.0 1.57079632679" xyz="0.0 0.0823 0.0" />
    </joint>
    <link name="ee_link">
        <collision>
            <geometry>
                <box size="0.01 0.01 0.01" />
            </geometry>
            <origin rpy="0 0 0" xyz="0 0 0" />
        </collision>
        
<inertial>
            <mass value="0.1" />
            <inertia ixx="0.03" iyy="0.03" izz="0.03" ixy="0.0" ixz="0.0" iyz="0.0" />
        </inertial>

    </link>
    <transmission name="shoulder_pan_trans">
        <type>transmission_interface/SimpleTransmission</type>
        <joint name="shoulder_pan_joint">
            <hardwareInterface>hardware_interface/PositionJointInterface</hardwareInterface>
        </joint>
        <actuator name="shoulder_pan_motor">
            <mechanicalReduction>1</mechanicalReduction>
        </actuator>
    </transmission>
    <transmission name="shoulder_lift_trans">
        <type>transmission_interface/SimpleTransmission</type>
        <joint name="shoulder_lift_joint">
            <hardwareInterface>hardware_interface/PositionJointInterface</hardwareInterface>
        </joint>
        <actuator name="shoulder_lift_motor">
            <mechanicalReduction>1</mechanicalReduction>
        </actuator>
    </transmission>
    <transmission name="elbow_trans">
        <type>transmission_interface/SimpleTransmission</type>
        <joint name="elbow_joint">
            <hardwareInterface>hardware_interface/PositionJointInterface</hardwareInterface>
        </joint>
        <actuator name="elbow_motor">
            <mechanicalReduction>1</mechanicalReduction>
        </actuator>
    </transmission>
    <transmission name="wrist_1_trans">
        <type>transmission_interface/SimpleTransmission</type>
        <joint name="wrist_1_joint">
            <hardwareInterface>hardware_interface/PositionJointInterface</hardwareInterface>
        </joint>
        <actuator name="wrist_1_motor">
            <mechanicalReduction>1</mechanicalReduction>
        </actuator>
    </transmission>
    <transmission name="wrist_2_trans">
        <type>transmission_interface/SimpleTransmission</type>
        <joint name="wrist_2_joint">
            <hardwareInterface>hardware_interface/PositionJointInterface</hardwareInterface>
        </joint>
        <actuator name="wrist_2_motor">
            <mechanicalReduction>1</mechanicalReduction>
        </actuator>
    </transmission>
    <transmission name="wrist_3_trans">
        <type>transmission_interface/SimpleTransmission</type>
        <joint name="wrist_3_joint">
            <hardwareInterface>hardware_interface/PositionJointInterface</hardwareInterface>
        </joint>
        <actuator name="wrist_3_motor">
            <mechanicalReduction>1</mechanicalReduction>
        </actuator>
    </transmission>
    <gazebo reference="shoulder_link">
        <selfCollide>true</selfCollide>
    </gazebo>
    <gazebo reference="upper_arm_link">
        <selfCollide>true</selfCollide>
    </gazebo>
    <gazebo reference="forearm_link">
        <selfCollide>true</selfCollide>
    </gazebo>
    <gazebo reference="wrist_1_link">
        <selfCollide>true</selfCollide>
    </gazebo>
    <gazebo reference="wrist_3_link">
        <selfCollide>true</selfCollide>
    </gazebo>
    <gazebo reference="wrist_2_link">
        <selfCollide>true</selfCollide>
    </gazebo>
    <gazebo reference="ee_link">
        <selfCollide>true</selfCollide>
    </gazebo>
    <!-- ROS base_link to UR 'Base' Coordinates transform -->
    <link name="base" />
    <joint name="base_link-base_fixed_joint" type="fixed">
        <!-- NOTE: this rotation is only needed as long as base_link itself is
                 not corrected wrt the real robot (ie: rotated over 180
                 degrees)
      -->
        <origin rpy="0 0 -3.14159265359" xyz="0 0 0" />
        <parent link="base_link" />
        <child link="base" />
    </joint>
    <!-- Frame coincident with all-zeros TCP on UR controller -->
    <link name="tool0" />
    <joint name="wrist_3_link-tool0_fixed_joint" type="fixed">
        <origin rpy="-1.57079632679 0 0" xyz="0 0.0823 0" />
        <parent link="wrist_3_link" />
        <child link="tool0" />
    </joint>
    <link name="gripper_body">
        
<inertial>
            <origin rpy="0 0 0" xyz="0.030743 -0.052447 0.02264" />
            <mass value="1.23381" />
            <inertia ixx="0.00020083" ixy="3.1979E-11" ixz="-1.5744E-22" iyy="0.00022836" iyz="-7.5039E-21" izz="0.00011851" />
        </inertial>

        <visual>
            <origin rpy="0 0 0" xyz="0 0 0" />
            <geometry>
                <mesh filename="package://gripper/meshes/gripper_body.STL" />
            </geometry>
            <material name="">
                <color rgba="0.79216 0.81961 0.93333 1" />
            </material>
        </visual>
        <collision>
            <origin rpy="0 0 0" xyz="0 0 0" />
            <geometry>
                <mesh filename="package://gripper/meshes/gripper_body.STL" />
            </geometry>
        </collision>
    </link>
    <link name="finger_link1">
        
<inertial>
            <origin rpy="0 0 0" xyz="-0.0055776 0.024687 9.7594E-11" />
            <mass value="0.41464" />
            <inertia ixx="3.0086E-06" ixy="6.4834E-09" ixz="3.2794E-13" iyy="6.6619E-07" iyz="2.6183E-13" izz="2.5138E-06" />
        </inertial>

        <visual>
            <origin rpy="0 0 0" xyz="0 0 0" />
            <geometry>
                <mesh filename="package://gripper/meshes/finger_link1.STL" />
            </geometry>
            <material name="">
                <color rgba="0.79216 0.81961 0.93333 1" />
            </material>
        </visual>
        <collision>
            <origin rpy="0 0 0" xyz="0 0 0" />
            <geometry>
                <mesh filename="package://gripper/meshes/finger_link1.STL" />
            </geometry>
        </collision>
    </link>
    <joint name="finger_joint1" type="prismatic">
        <origin rpy="1.5708 0 3.1416" xyz="0.050359 -0.052447 0.069837" />
        <parent link="gripper_body" />
        <child link="finger_link1" />
        <axis xyz="1 0 0" />
        <limit effort="100" lower="0.00" upper="0.02" velocity="0.1" />
        <dynamics damping="0.7" />
    </joint>
    <link name="finger_link2">
        
<inertial>
            <origin rpy="0 0 0" xyz="0.0051896 0.024687 9.7594E-11" />
            <mass value="0.41464" />
            <inertia ixx="3.0086E-06" ixy="6.4834E-09" ixz="3.2794E-13" iyy="6.6619E-07" iyz="2.6183E-13" izz="2.5138E-06" />
        </inertial>

        <visual>
            <origin rpy="0 0 0" xyz="0 0 0" />
            <geometry>
                <mesh filename="package://gripper/meshes/finger_link2.STL" />
            </geometry>
            <material name="">
                <color rgba="0.79216 0.81961 0.93333 1" />
            </material>
        </visual>
        <collision>
            <origin rpy="0 0 0" xyz="0 0 0" />
            <geometry>
                <mesh filename="package://gripper/meshes/finger_link2.STL" />
            </geometry>
        </collision>
    </link>
    <joint name="finger_joint2" type="prismatic">
        <origin rpy="1.5708 0 0" xyz="0.00035895 -0.052447 0.069837" />
        <parent link="gripper_body" />
        <child link="finger_link2" />
        <axis xyz="1 0 0" />
        <limit effort="100" lower="0.00" upper="0.02" velocity="0.1" />
        <dynamics damping="0.7" />
    </joint>
    <gazebo reference="finger_link2">
        <kp>1000000.0</kp>
        <kd>100.0</kd>
        <mu1>1.0</mu1>
        <mu2>1.0</mu2>
        <maxVel>0</maxVel>
        <minDepth>0.1</minDepth>
    </gazebo>
    <gazebo reference="finger_link1">
        <kp>1000000.0</kp>
        <kd>100.0</kd>
        <mu1>1.0</mu1>
        <mu2>1.0</mu2>
        <maxVel>0</maxVel>
        <minDepth>0.1</minDepth>
    </gazebo>
    <transmission name="finger1_trans">
        <type>transmission_interface/SimpleTransmission</type>
        <joint name="finger_joint1">
            <hardwareInterface>hardware_interface/PositionJointInterface</hardwareInterface>
        </joint>
        <actuator name="motor1">
            <hardwareInterface>hardware_interface/PositionJointInterface</hardwareInterface>
            <mechanicalReduction>1</mechanicalReduction>
        </actuator>
    </transmission>
    <transmission name="finger2_trans">
        <type>transmission_interface/SimpleTransmission</type>
        <joint name="finger_joint2">
            <hardwareInterface>hardware_interface/PositionJointInterface</hardwareInterface>
        </joint>
        <actuator name="motor2">
            <hardwareInterface>hardware_interface/PositionJointInterface</hardwareInterface>
            <mechanicalReduction>1</mechanicalReduction>
        </actuator>
    </transmission>
    <gazebo reference="gripper_body">
        <material>Gazebo/DarkGrey</material>
    </gazebo>
    <gazebo reference="finger_link1">
        <material>Gazebo/DarkGrey</material>
    </gazebo>
    <gazebo reference="finger_link2">
        <material>Gazebo/DarkGrey</material>
    </gazebo>
    <joint name="ur5_gripper_joint" type="fixed">
        <origin rpy="0 0 0" xyz="-0.030 0.052 0.007" />
        <parent link="tool0" />
        <child link="gripper_body" />
    </joint>
    <!-- FIXME: what is this offset? -->
    <joint name="KinectSensor2_kinect2_joint" type="fixed">
        <origin rpy="0 1.57079632679 0" xyz="0.5 0 1.3" />
        <parent link="world" />
        <child link="KinectSensor2_kinect2_link" />
    </joint>
    <link name="KinectSensor2_kinect2_link">
        
<inertial>
            <mass value="0.1" />
            <origin rpy="0 0 0" xyz="0 0 0" />
            <inertia ixx="0.01" ixy="0.0" ixz="0.0" iyy="0.01" iyz="0.0" izz="0.01" />
        </inertial>

        <visual>
            <origin rpy="0 0 0" xyz="-0.102 -0.148 0" />
            <geometry>
                <mesh filename="package://common_sensors/meshes/sensors/kinect2_assembly.dae" scale="0.001 0.001 0.001" />
            </geometry>
            <material name="gray">
                <color rgba="0.95 0.95 0.95 1" />
            </material>
        </visual>
        <collision>
            <origin rpy="0 0 0" xyz="0 0 0" />
            <geometry>
                <sphere radius="0.0005" />
            </geometry>
        </collision>
    </link>
    <!-- kinect2 ir sensor physical attachment -->
    <joint name="KinectSensor2_kinect2_ir_joint" type="fixed">
        <origin rpy="0 0 0" xyz="-0.032267 -0.0475 0.155" />
        <parent link="KinectSensor2_kinect2_link" />
        <child link="KinectSensor2_kinect2_ir_link" />
    </joint>
    <link name="KinectSensor2_kinect2_ir_link">
        
<inertial>
            <mass value="0.1" />
            <origin rpy="0 0 0" xyz="0 0 0" />
            <inertia ixx="0.01" ixy="0.0" ixz="0.0" iyy="0.01" iyz="0.0" izz="0.01" />
        </inertial>

        <visual>
            <origin rpy="0 0 0" xyz="0.0 0.0 0" />
            <geometry>
                <sphere radius="0.0005" />
            </geometry>
        </visual>
        <collision>
            <origin rpy="0 0 0" xyz="0.0 0.0 0" />
            <geometry>
                <sphere radius="0.0005" />
            </geometry>
        </collision>
    </link>
    <!-- kinect2 ir sensor frame -->
    <joint name="KinectSensor2_kinect2_ir_optical_frame_joint" type="fixed">
        <origin rpy="-1.57079632679       0.0               -1.57079632679" xyz="0.0                  0.01 0.0" />
        <parent link="KinectSensor2_kinect2_ir_link" />
        <child link="KinectSensor2_kinect2_ir_optical_frame" />
    </joint>
    <link name="KinectSensor2_kinect2_ir_optical_frame" />
    <gazebo reference="KinectSensor2_kinect2_ir_link">
        <sensor name="KinectSensor2_ir_sensor" type="depth">
            <always_on>true</always_on>
            <update_rate>20.0</update_rate>
            <camera>
                <horizontal_fov>0.994837673637</horizontal_fov>
                <image>
                    <format>L8</format>
                    <width>640</width>
                    <height>480</height>
                </image>
                <clip>
                    <near>0.01</near>
                    <far>5</far>
                </clip>
            </camera>
            <plugin filename="libgazebo_ros_openni_kinect.so" name="KinectSensor2_kinect2_ir_link_controller">
                <baseline>0.2</baseline>
                <alwaysOn>true</alwaysOn>
                <updateRate>10.0</updateRate>
                <cameraName>kinect2_ir</cameraName>
                <imageTopicName>/kinect2/ir/image_raw</imageTopicName>
                <cameraInfoTopicName>/kinect2/ir/camera_info</cameraInfoTopicName>
                <depthImageTopicName>/kinect2/depth/image_raw</depthImageTopicName>
                <depthImageCameraInfoTopicName>/kinect2/depth/camera_info</depthImageCameraInfoTopicName>
                <pointCloudTopicName>/kinect2/depth/points</pointCloudTopicName>
                <frameName>KinectSensor2_kinect2_ir_optical_frame</frameName>
                <pointCloudCutoff>0.5</pointCloudCutoff>
                <distortionK1>0.00000001</distortionK1>
                <distortionK2>0.00000001</distortionK2>
                <distortionK3>0.00000001</distortionK3>
                <distortionT1>0.00000001</distortionT1>
                <distortionT2>0.00000001</distortionT2>
                <CxPrime>0</CxPrime>
                <Cx>0</Cx>
                <Cy>0</Cy>
                <focalLength>0</focalLength>
                <hackBaseline>0</hackBaseline>
            </plugin>
        </sensor>
        <material value="Gazebo/Red" />
    </gazebo>
    <!-- kinect2 rgb sensor physical attachment -->
    <joint name="KinectSensor2_kinect2_rgb_joint" type="fixed">
        <origin rpy="0 0 0" xyz="0 -0.05175 0" />
        <parent link="KinectSensor2_kinect2_ir_link" />
        <child link="KinectSensor2_kinect2_rgb_link" />
    </joint>
    <link name="KinectSensor2_kinect2_rgb_link">
        
<inertial>
            <mass value="0.1" />
            <origin rpy="0 0 0" xyz="0 0 0" />
            <inertia ixx="0.01" ixy="0.0" ixz="0.0" iyy="0.01" iyz="0.0" izz="0.01" />
        </inertial>

        <visual>
            <origin rpy="-1.57079632679 0.0         -1.57079632679" xyz="0.0            0.0                 0.0" />
            <geometry>
                <sphere radius="0.0005" />
            </geometry>
        </visual>
        <collision>
            <origin rpy="0 0 0" xyz="0.0 0.0 0" />
            <geometry>
                <sphere radius="0.0005" />
            </geometry>
        </collision>
    </link>
    <!-- kinect2 rgb sensor frame -->
    <joint name="KinectSensor2_kinect2_rgb_optical_frame_joint" type="fixed">
        <origin rpy="-1.57079632679 0.0         -1.57079632679" xyz="0.0            0.0                 0.0" />
        <parent link="KinectSensor2_kinect2_rgb_link" />
        <child link="KinectSensor2_kinect2_rgb_optical_frame" />
    </joint>
    <link name="KinectSensor2_kinect2_rgb_optical_frame" />
    <gazebo reference="KinectSensor2_kinect2_rgb_link">
        <sensor name="KinectSensor2_rgb_sensor" type="depth">
            <always_on>true</always_on>
            <update_rate>20.0</update_rate>
            <camera>
                <horizontal_fov>0.994837673637</horizontal_fov>
                <image>
                    <format>B8G8R8</format>
                    <width>1280</width>
                    <height>960</height>
                </image>
                <clip>
                    <near>0.01</near>
                    <far>5</far>
                </clip>
            </camera>
            <plugin filename="libgazebo_ros_openni_kinect.so" name="KinectSensor2_kinect2_rgb_link_controller">
                <alwaysOn>true</alwaysOn>
                <updateRate>10.0</updateRate>
                <cameraName>kinect2_rgb</cameraName>
                <imageTopicName>/kinect2/rgb/image_raw</imageTopicName>
                <cameraInfoTopicName>/kinect2/rgb/camera_info</cameraInfoTopicName>
                <depthImageTopicName>/kinect2/depth/image_raw</depthImageTopicName>
                <depthImageCameraInfoTopicName>/kinect2/depth/camera_info</depthImageCameraInfoTopicName>
                <pointCloudTopicName>/kinect2/depth_registered/points</pointCloudTopicName>
                <frameName>KinectSensor2_kinect2_rgb_optical_frame</frameName>
                <pointCloudCutoff>0.5</pointCloudCutoff>
                <distortionK1>0.00000001</distortionK1>
                <distortionK2>0.00000001</distortionK2>
                <distortionK3>0.00000001</distortionK3>
                <distortionT1>0.00000001</distortionT1>
                <distortionT2>0.00000001</distortionT2>
                <CxPrime>0</CxPrime>
                <Cx>0</Cx>
                <Cy>0</Cy>
                <focalLength>0</focalLength>
                <hackBaseline>0</hackBaseline>
            </plugin>
        </sensor>
        <material value="Gazebo/Red" />
    </gazebo>
    <!-- Used for fixing ur to Gazebo 'world' -->
    <link name="world" />
    <joint name="world_joint" type="fixed">
        <parent link="world" />
        <child link="base_link" />
        <origin rpy="0.0 0.0 0.0" xyz="0.0 0.0 0.0" />
    </joint>
    <gazebo>
        <plugin filename="libgazebo_grasp_fix.so" name="gazebo_grasp_fix">
            <!--
            NOTE: The finger tips are linked together with the links before, because they are connected with a
			fixed joint. Gazebo makes one whole link out of this automatically. When listing the 9_*_tip links
			here, they won't be found in the SDF.
            -->
            <arm>
                <arm_name>ur_gripper</arm_name>
                <palm_link>wrist_3_link</palm_link>
                <gripper_link>finger_link1</gripper_link>
                <gripper_link>finger_link2</gripper_link>
            </arm>
            <forces_angle_tolerance>100</forces_angle_tolerance>
            <update_rate>20</update_rate>
            <grip_count_threshold>1</grip_count_threshold>
            <max_grip_count>3</max_grip_count>
            <release_tolerance>0.0198</release_tolerance>
            <!-- 0.01977<0.0198<0.01999 -->
            <disable_collisions_on_attach>false</disable_collisions_on_attach>
            <contact_topic>__default_topic__</contact_topic>
        </plugin>
    </gazebo>
    <transmission name="trans_shoulder_pan_joint">
        <type>transmission_interface/SimpleTransmission</type>
        <joint name="shoulder_pan_joint">
            <hardwareInterface>hardware_interface/EffortJointInterface</hardwareInterface>
        </joint>
        <actuator name="shoulder_pan_joint_motor">
            <hardwareInterface>hardware_interface/EffortJointInterface</hardwareInterface>
            <mechanicalReduction>1</mechanicalReduction>
        </actuator>
    </transmission>
    <transmission name="trans_shoulder_lift_joint">
        <type>transmission_interface/SimpleTransmission</type>
        <joint name="shoulder_lift_joint">
            <hardwareInterface>hardware_interface/EffortJointInterface</hardwareInterface>
        </joint>
        <actuator name="shoulder_lift_joint_motor">
            <hardwareInterface>hardware_interface/EffortJointInterface</hardwareInterface>
            <mechanicalReduction>1</mechanicalReduction>
        </actuator>
    </transmission>
    <transmission name="trans_elbow_joint">
        <type>transmission_interface/SimpleTransmission</type>
        <joint name="elbow_joint">
            <hardwareInterface>hardware_interface/EffortJointInterface</hardwareInterface>
        </joint>
        <actuator name="elbow_joint_motor">
            <hardwareInterface>hardware_interface/EffortJointInterface</hardwareInterface>
            <mechanicalReduction>1</mechanicalReduction>
        </actuator>
    </transmission>
    <transmission name="trans_wrist_1_joint">
        <type>transmission_interface/SimpleTransmission</type>
        <joint name="wrist_1_joint">
            <hardwareInterface>hardware_interface/EffortJointInterface</hardwareInterface>
        </joint>
        <actuator name="wrist_1_joint_motor">
            <hardwareInterface>hardware_interface/EffortJointInterface</hardwareInterface>
            <mechanicalReduction>1</mechanicalReduction>
        </actuator>
    </transmission>
    <transmission name="trans_wrist_2_joint">
        <type>transmission_interface/SimpleTransmission</type>
        <joint name="wrist_2_joint">
            <hardwareInterface>hardware_interface/EffortJointInterface</hardwareInterface>
        </joint>
        <actuator name="wrist_2_joint_motor">
            <hardwareInterface>hardware_interface/EffortJointInterface</hardwareInterface>
            <mechanicalReduction>1</mechanicalReduction>
        </actuator>
    </transmission>
    <transmission name="trans_wrist_3_joint">
        <type>transmission_interface/SimpleTransmission</type>
        <joint name="wrist_3_joint">
            <hardwareInterface>hardware_interface/EffortJointInterface</hardwareInterface>
        </joint>
        <actuator name="wrist_3_joint_motor">
            <hardwareInterface>hardware_interface/EffortJointInterface</hardwareInterface>
            <mechanicalReduction>1</mechanicalReduction>
        </actuator>
    </transmission>
    <transmission name="trans_finger_joint1">
        <type>transmission_interface/SimpleTransmission</type>
        <joint name="finger_joint1">
            <hardwareInterface>hardware_interface/EffortJointInterface</hardwareInterface>
        </joint>
        <actuator name="finger_joint1_motor">
            <hardwareInterface>hardware_interface/EffortJointInterface</hardwareInterface>
            <mechanicalReduction>1</mechanicalReduction>
        </actuator>
    </transmission>
    <transmission name="trans_finger_joint2">
        <type>transmission_interface/SimpleTransmission</type>
        <joint name="finger_joint2">
            <hardwareInterface>hardware_interface/EffortJointInterface</hardwareInterface>
        </joint>
        <actuator name="finger_joint2_motor">
            <hardwareInterface>hardware_interface/EffortJointInterface</hardwareInterface>
            <mechanicalReduction>1</mechanicalReduction>
        </actuator>
    </transmission>
    <gazebo>
        <plugin name="gazebo_ros_control" filename="libgazebo_ros_control.so">
            <robotNamespace>/</robotNamespace>
        </plugin>
    </gazebo>
</robot>

<transmission name="shoulder_pan_trans">
        <type>transmission_interface/SimpleTransmission</type>
        <joint name="shoulder_pan_joint">
            <hardwareInterface>hardware_interface/PositionJointInterface</hardwareInterface>
        </joint>
        <actuator name="shoulder_pan_motor">
            <mechanicalReduction>1</mechanicalReduction>
        </actuator>
    </transmission>
    <transmission name="shoulder_lift_trans">
        <type>transmission_interface/SimpleTransmission</type>
        <joint name="shoulder_lift_joint">
            <hardwareInterface>hardware_interface/PositionJointInterface</hardwareInterface>
        </joint>
        <actuator name="shoulder_lift_motor">
            <mechanicalReduction>1</mechanicalReduction>
        </actuator>
    </transmission>
    <transmission name="elbow_trans">
        <type>transmission_interface/SimpleTransmission</type>
        <joint name="elbow_joint">
            <hardwareInterface>hardware_interface/PositionJointInterface</hardwareInterface>
        </joint>
        <actuator name="elbow_motor">
            <mechanicalReduction>1</mechanicalReduction>
        </actuator>
    </transmission>
    <transmission name="wrist_1_trans">
        <type>transmission_interface/SimpleTransmission</type>
        <joint name="wrist_1_joint">
            <hardwareInterface>hardware_interface/PositionJointInterface</hardwareInterface>
        </joint>
        <actuator name="wrist_1_motor">
            <mechanicalReduction>1</mechanicalReduction>
        </actuator>
    </transmission>
    <transmission name="wrist_2_trans">
        <type>transmission_interface/SimpleTransmission</type>
        <joint name="wrist_2_joint">
            <hardwareInterface>hardware_interface/PositionJointInterface</hardwareInterface>
        </joint>
        <actuator name="wrist_2_motor">
            <mechanicalReduction>1</mechanicalReduction>
        </actuator>
    </transmission>
    <transmission name="wrist_3_trans">
        <type>transmission_interface/SimpleTransmission</type>
        <joint name="wrist_3_joint">
            <hardwareInterface>hardware_interface/PositionJointInterface</hardwareInterface>
        </joint>
        <actuator name="wrist_3_motor">
            <mechanicalReduction>1</mechanicalReduction>
        </actuator>
    </transmission>
    <gazebo reference="shoulder_link">
        <selfCollide>true</selfCollide>
    </gazebo>
    <gazebo reference="upper_arm_link">
        <selfCollide>true</selfCollide>
    </gazebo>
    <gazebo reference="forearm_link">
        <selfCollide>true</selfCollide>
    </gazebo>
    <gazebo reference="wrist_1_link">
        <selfCollide>true</selfCollide>
    </gazebo>
    <gazebo reference="wrist_3_link">
        <selfCollide>true</selfCollide>
    </gazebo>
    <gazebo reference="wrist_2_link">
        <selfCollide>true</selfCollide>
    </gazebo>
    <gazebo reference="ee_link">
        <selfCollide>true</selfCollide>
    </gazebo>
    <!-- ROS base_link to UR 'Base' Coordinates transform -->
    <link name="base" />
    <joint name="base_link-base_fixed_joint" type="fixed">
        <!-- NOTE: this rotation is only needed as long as base_link itself is
                 not corrected wrt the real robot (ie: rotated over 180
                 degrees)
      -->
        <origin rpy="0 0 -3.14159265359" xyz="0 0 0" />
        <parent link="base_link" />
        <child link="base" />
    </joint>
    <!-- Frame coincident with all-zeros TCP on UR controller -->
    <link name="tool0" />
    <joint name="wrist_3_link-tool0_fixed_joint" type="fixed">
        <origin rpy="-1.57079632679 0 0" xyz="0 0.0823 0" />
        <parent link="wrist_3_link" />
        <child link="tool0" />
    </joint>
    <link name="gripper_body">
        <inertial>
            <origin rpy="0 0 0" xyz="0.030743 -0.052447 0.02264" />
            <mass value="1.23381" />
            <inertia ixx="0.00020083" ixy="3.1979E-11" ixz="-1.5744E-22" iyy="0.00022836" iyz="-7.5039E-21" izz="0.00011851" />
        </inertial>
        <visual>
            <origin rpy="0 0 0" xyz="0 0 0" />
            <geometry>
                <mesh filename="package://gripper/meshes/gripper_body.STL" />
            </geometry>
            <material name="">
                <color rgba="0.79216 0.81961 0.93333 1" />
            </material>
        </visual>
        <collision>
            <origin rpy="0 0 0" xyz="0 0 0" />
            <geometry>
                <mesh filename="package://gripper/meshes/gripper_body.STL" />
            </geometry>
        </collision>
    </link>
    <link name="finger_link1">
        <inertial>
            <origin rpy="0 0 0" xyz="-0.0055776 0.024687 9.7594E-11" />
            <mass value="0.41464" />
            <inertia ixx="3.0086E-06" ixy="6.4834E-09" ixz="3.2794E-13" iyy="6.6619E-07" iyz="2.6183E-13" izz="2.5138E-06" />
        </inertial>
        <visual>
            <origin rpy="0 0 0" xyz="0 0 0" />
            <geometry>
                <mesh filename="package://gripper/meshes/finger_link1.STL" />
            </geometry>
            <material name="">
                <color rgba="0.79216 0.81961 0.93333 1" />
            </material>
        </visual>
        <collision>
            <origin rpy="0 0 0" xyz="0 0 0" />
            <geometry>
                <mesh filename="package://gripper/meshes/finger_link1.STL" />
            </geometry>
        </collision>
    </link>
    <joint name="finger_joint1" type="prismatic">
        <origin rpy="1.5708 0 3.1416" xyz="0.050359 -0.052447 0.069837" />
        <parent link="gripper_body" />
        <child link="finger_link1" />
        <axis xyz="1 0 0" />
        <limit effort="100" lower="0.00" upper="0.02" velocity="0.1" />
        <dynamics damping="0.7" />
    </joint>
    <link name="finger_link2">
        <inertial>
            <origin rpy="0 0 0" xyz="0.0051896 0.024687 9.7594E-11" />
            <mass value="0.41464" />
            <inertia ixx="3.0086E-06" ixy="6.4834E-09" ixz="3.2794E-13" iyy="6.6619E-07" iyz="2.6183E-13" izz="2.5138E-06" />
        </inertial>
        <visual>
            <origin rpy="0 0 0" xyz="0 0 0" />
            <geometry>
                <mesh filename="package://gripper/meshes/finger_link2.STL" />
            </geometry>
            <material name="">
                <color rgba="0.79216 0.81961 0.93333 1" />
            </material>
        </visual>
        <collision>
            <origin rpy="0 0 0" xyz="0 0 0" />
            <geometry>
                <mesh filename="package://gripper/meshes/finger_link2.STL" />
            </geometry>
        </collision>
    </link>
    <joint name="finger_joint2" type="prismatic">
        <origin rpy="1.5708 0 0" xyz="0.00035895 -0.052447 0.069837" />
        <parent link="gripper_body" />
        <child link="finger_link2" />
        <axis xyz="1 0 0" />
        <limit effort="100" lower="0.00" upper="0.02" velocity="0.1" />
        <dynamics damping="0.7" />
    </joint>
    <gazebo reference="finger_link2">
        <kp>1000000.0</kp>
        <kd>100.0</kd>
        <mu1>1.0</mu1>
        <mu2>1.0</mu2>
        <maxVel>0</maxVel>
        <minDepth>0.1</minDepth>
    </gazebo>
    <gazebo reference="finger_link1">
        <kp>1000000.0</kp>
        <kd>100.0</kd>
        <mu1>1.0</mu1>
        <mu2>1.0</mu2>
        <maxVel>0</maxVel>
        <minDepth>0.1</minDepth>
    </gazebo>
    <transmission name="finger1_trans">
        <type>transmission_interface/SimpleTransmission</type>
        <joint name="finger_joint1">
            <hardwareInterface>hardware_interface/PositionJointInterface</hardwareInterface>
        </joint>
        <actuator name="motor1">
            <hardwareInterface>hardware_interface/PositionJointInterface</hardwareInterface>
            <mechanicalReduction>1</mechanicalReduction>
        </actuator>
    </transmission>
    <transmission name="finger2_trans">
        <type>transmission_interface/SimpleTransmission</type>
        <joint name="finger_joint2">
            <hardwareInterface>hardware_interface/PositionJointInterface</hardwareInterface>
        </joint>
        <actuator name="motor2">
            <hardwareInterface>hardware_interface/PositionJointInterface</hardwareInterface>
            <mechanicalReduction>1</mechanicalReduction>
        </actuator>
    </transmission>
    <gazebo reference="gripper_body">
        <material>Gazebo/DarkGrey</material>
    </gazebo>
    <gazebo reference="finger_link1">
        <material>Gazebo/DarkGrey</material>
    </gazebo>
    <gazebo reference="finger_link2">
        <material>Gazebo/DarkGrey</material>
    </gazebo>
    <joint name="ur5_gripper_joint" type="fixed">
        <origin rpy="0 0 0" xyz="-0.030 0.052 0.007" />
        <parent link="tool0" />
        <child link="gripper_body" />
    </joint>
    <!-- FIXME: what is this offset? -->
    <joint name="KinectSensor2_kinect2_joint" type="fixed">
        <origin rpy="0 1.57079632679 0" xyz="0.5 0 1.3" />
        <parent link="world" />
        <child link="KinectSensor2_kinect2_link" />
    </joint>
    <link name="KinectSensor2_kinect2_link">
        <inertial>
            <mass value="0.1" />
            <origin rpy="0 0 0" xyz="0 0 0" />
            <inertia ixx="0.01" ixy="0.0" ixz="0.0" iyy="0.01" iyz="0.0" izz="0.01" />
        </inertial>
        <visual>
            <origin rpy="0 0 0" xyz="-0.102 -0.148 0" />
            <geometry>
                <mesh filename="package://common_sensors/meshes/sensors/kinect2_assembly.dae" scale="0.001 0.001 0.001" />
            </geometry>
            <material name="gray">
                <color rgba="0.95 0.95 0.95 1" />
            </material>
        </visual>
        <collision>
            <origin rpy="0 0 0" xyz="0 0 0" />
            <geometry>
                <sphere radius="0.0005" />
            </geometry>
        </collision>
    </link>
    <!-- kinect2 ir sensor physical attachment -->
    <joint name="KinectSensor2_kinect2_ir_joint" type="fixed">
        <origin rpy="0 0 0" xyz="-0.032267 -0.0475 0.155" />
        <parent link="KinectSensor2_kinect2_link" />
        <child link="KinectSensor2_kinect2_ir_link" />
    </joint>
    <link name="KinectSensor2_kinect2_ir_link">
        <inertial>
            <mass value="0.1" />
            <origin rpy="0 0 0" xyz="0 0 0" />
            <inertia ixx="0.01" ixy="0.0" ixz="0.0" iyy="0.01" iyz="0.0" izz="0.01" />
        </inertial>
        <visual>
            <origin rpy="0 0 0" xyz="0.0 0.0 0" />
            <geometry>
                <sphere radius="0.0005" />
            </geometry>
        </visual>
        <collision>
            <origin rpy="0 0 0" xyz="0.0 0.0 0" />
            <geometry>
                <sphere radius="0.0005" />
            </geometry>
        </collision>
    </link>
    <!-- kinect2 ir sensor frame -->
    <joint name="KinectSensor2_kinect2_ir_optical_frame_joint" type="fixed">
        <origin rpy="-1.57079632679       0.0               -1.57079632679" xyz="0.0                  0.01 0.0" />
        <parent link="KinectSensor2_kinect2_ir_link" />
        <child link="KinectSensor2_kinect2_ir_optical_frame" />
    </joint>
    <link name="KinectSensor2_kinect2_ir_optical_frame" />
    <gazebo reference="KinectSensor2_kinect2_ir_link">
        <sensor name="KinectSensor2_ir_sensor" type="depth">
            <always_on>true</always_on>
            <update_rate>20.0</update_rate>
            <camera>
                <horizontal_fov>0.994837673637</horizontal_fov>
                <image>
                    <format>L8</format>
                    <width>640</width>
                    <height>480</height>
                </image>
                <clip>
                    <near>0.01</near>
                    <far>5</far>
                </clip>
            </camera>
            <plugin filename="libgazebo_ros_openni_kinect.so" name="KinectSensor2_kinect2_ir_link_controller">
                <baseline>0.2</baseline>
                <alwaysOn>true</alwaysOn>
                <updateRate>10.0</updateRate>
                <cameraName>kinect2_ir</cameraName>
                <imageTopicName>/kinect2/ir/image_raw</imageTopicName>
                <cameraInfoTopicName>/kinect2/ir/camera_info</cameraInfoTopicName>
                <depthImageTopicName>/kinect2/depth/image_raw</depthImageTopicName>
                <depthImageCameraInfoTopicName>/kinect2/depth/camera_info</depthImageCameraInfoTopicName>
                <pointCloudTopicName>/kinect2/depth/points</pointCloudTopicName>
                <frameName>KinectSensor2_kinect2_ir_optical_frame</frameName>
                <pointCloudCutoff>0.5</pointCloudCutoff>
                <distortionK1>0.00000001</distortionK1>
                <distortionK2>0.00000001</distortionK2>
                <distortionK3>0.00000001</distortionK3>
                <distortionT1>0.00000001</distortionT1>
                <distortionT2>0.00000001</distortionT2>
                <CxPrime>0</CxPrime>
                <Cx>0</Cx>
                <Cy>0</Cy>
                <focalLength>0</focalLength>
                <hackBaseline>0</hackBaseline>
            </plugin>
        </sensor>
        <material value="Gazebo/Red" />
    </gazebo>
    <!-- kinect2 rgb sensor physical attachment -->
    <joint name="KinectSensor2_kinect2_rgb_joint" type="fixed">
        <origin rpy="0 0 0" xyz="0 -0.05175 0" />
        <parent link="KinectSensor2_kinect2_ir_link" />
        <child link="KinectSensor2_kinect2_rgb_link" />
    </joint>
    <link name="KinectSensor2_kinect2_rgb_link">
        <inertial>
            <mass value="0.1" />
            <origin rpy="0 0 0" xyz="0 0 0" />
            <inertia ixx="0.01" ixy="0.0" ixz="0.0" iyy="0.01" iyz="0.0" izz="0.01" />
        </inertial>
        <visual>
            <origin rpy="-1.57079632679 0.0         -1.57079632679" xyz="0.0            0.0                 0.0" />
            <geometry>
                <sphere radius="0.0005" />
            </geometry>
        </visual>
        <collision>
            <origin rpy="0 0 0" xyz="0.0 0.0 0" />
            <geometry>
                <sphere radius="0.0005" />
            </geometry>
        </collision>
    </link>
    <!-- kinect2 rgb sensor frame -->
    <joint name="KinectSensor2_kinect2_rgb_optical_frame_joint" type="fixed">
        <origin rpy="-1.57079632679 0.0         -1.57079632679" xyz="0.0            0.0                 0.0" />
        <parent link="KinectSensor2_kinect2_rgb_link" />
        <child link="KinectSensor2_kinect2_rgb_optical_frame" />
    </joint>
    <link name="KinectSensor2_kinect2_rgb_optical_frame" />
    <gazebo reference="KinectSensor2_kinect2_rgb_link">
        <sensor name="KinectSensor2_rgb_sensor" type="depth">
            <always_on>true</always_on>
            <update_rate>20.0</update_rate>
            <camera>
                <horizontal_fov>0.994837673637</horizontal_fov>
                <image>
                    <format>B8G8R8</format>
                    <width>1280</width>
                    <height>960</height>
                </image>
                <clip>
                    <near>0.01</near>
                    <far>5</far>
                </clip>
            </camera>
            <plugin filename="libgazebo_ros_openni_kinect.so" name="KinectSensor2_kinect2_rgb_link_controller">
                <alwaysOn>true</alwaysOn>
                <updateRate>10.0</updateRate>
                <cameraName>kinect2_rgb</cameraName>
                <imageTopicName>/kinect2/rgb/image_raw</imageTopicName>
                <cameraInfoTopicName>/kinect2/rgb/camera_info</cameraInfoTopicName>
                <depthImageTopicName>/kinect2/depth/image_raw</depthImageTopicName>
                <depthImageCameraInfoTopicName>/kinect2/depth/camera_info</depthImageCameraInfoTopicName>
                <pointCloudTopicName>/kinect2/depth_registered/points</pointCloudTopicName>
                <frameName>KinectSensor2_kinect2_rgb_optical_frame</frameName>
                <pointCloudCutoff>0.5</pointCloudCutoff>
                <distortionK1>0.00000001</distortionK1>
                <distortionK2>0.00000001</distortionK2>
                <distortionK3>0.00000001</distortionK3>
                <distortionT1>0.00000001</distortionT1>
                <distortionT2>0.00000001</distortionT2>
                <CxPrime>0</CxPrime>
                <Cx>0</Cx>
                <Cy>0</Cy>
                <focalLength>0</focalLength>
                <hackBaseline>0</hackBaseline>
            </plugin>
        </sensor>
        <material value="Gazebo/Red" />
    </gazebo>
    <!-- Used for fixing ur to Gazebo 'world' -->
    <link name="world" />
    <joint name="world_joint" type="fixed">
        <parent link="world" />
        <child link="base_link" />
        <origin rpy="0.0 0.0 0.0" xyz="0.0 0.0 0.0" />
    </joint>
    <gazebo>
        <plugin filename="libgazebo_grasp_fix.so" name="gazebo_grasp_fix">
            <!--
            NOTE: The finger tips are linked together with the links before, because they are connected with a
			fixed joint. Gazebo makes one whole link out of this automatically. When listing the 9_*_tip links
			here, they won't be found in the SDF.
            -->
            <arm>
                <arm_name>ur_gripper</arm_name>
                <palm_link>wrist_3_link</palm_link>
                <gripper_link>finger_link1</gripper_link>
                <gripper_link>finger_link2</gripper_link>
            </arm>
            <forces_angle_tolerance>100</forces_angle_tolerance>
            <update_rate>20</update_rate>
            <grip_count_threshold>1</grip_count_threshold>
            <max_grip_count>3</max_grip_count>
            <release_tolerance>0.0198</release_tolerance>
            <!-- 0.01977<0.0198<0.01999 -->
            <disable_collisions_on_attach>false</disable_collisions_on_attach>
            <contact_topic>__default_topic__</contact_topic>
        </plugin>
    </gazebo>
    <transmission name="trans_shoulder_pan_joint">
        <type>transmission_interface/SimpleTransmission</type>
        <joint name="shoulder_pan_joint">
            <hardwareInterface>hardware_interface/EffortJointInterface</hardwareInterface>
        </joint>
        <actuator name="shoulder_pan_joint_motor">
            <hardwareInterface>hardware_interface/EffortJointInterface</hardwareInterface>
            <mechanicalReduction>1</mechanicalReduction>
        </actuator>
    </transmission>
    <transmission name="trans_shoulder_lift_joint">
        <type>transmission_interface/SimpleTransmission</type>
        <joint name="shoulder_lift_joint">
            <hardwareInterface>hardware_interface/EffortJointInterface</hardwareInterface>
        </joint>
        <actuator name="shoulder_lift_joint_motor">
            <hardwareInterface>hardware_interface/EffortJointInterface</hardwareInterface>
            <mechanicalReduction>1</mechanicalReduction>
        </actuator>
    </transmission>
    <transmission name="trans_elbow_joint">
        <type>transmission_interface/SimpleTransmission</type>
        <joint name="elbow_joint">
            <hardwareInterface>hardware_interface/EffortJointInterface</hardwareInterface>
        </joint>
        <actuator name="elbow_joint_motor">
            <hardwareInterface>hardware_interface/EffortJointInterface</hardwareInterface>
            <mechanicalReduction>1</mechanicalReduction>
        </actuator>
    </transmission>
    <transmission name="trans_wrist_1_joint">
        <type>transmission_interface/SimpleTransmission</type>
        <joint name="wrist_1_joint">
            <hardwareInterface>hardware_interface/EffortJointInterface</hardwareInterface>
        </joint>
        <actuator name="wrist_1_joint_motor">
            <hardwareInterface>hardware_interface/EffortJointInterface</hardwareInterface>
            <mechanicalReduction>1</mechanicalReduction>
        </actuator>
    </transmission>
    <transmission name="trans_wrist_2_joint">
        <type>transmission_interface/SimpleTransmission</type>
        <joint name="wrist_2_joint">
            <hardwareInterface>hardware_interface/EffortJointInterface</hardwareInterface>
        </joint>
        <actuator name="wrist_2_joint_motor">
            <hardwareInterface>hardware_interface/EffortJointInterface</hardwareInterface>
            <mechanicalReduction>1</mechanicalReduction>
        </actuator>
    </transmission>
    <transmission name="trans_wrist_3_joint">
        <type>transmission_interface/SimpleTransmission</type>
        <joint name="wrist_3_joint">
            <hardwareInterface>hardware_interface/EffortJointInterface</hardwareInterface>
        </joint>
        <actuator name="wrist_3_joint_motor">
            <hardwareInterface>hardware_interface/EffortJointInterface</hardwareInterface>
            <mechanicalReduction>1</mechanicalReduction>
        </actuator>
    </transmission>
    <transmission name="trans_finger_joint1">
        <type>transmission_interface/SimpleTransmission</type>
        <joint name="finger_joint1">
            <hardwareInterface>hardware_interface/EffortJointInterface</hardwareInterface>
        </joint>
        <actuator name="finger_joint1_motor">
            <hardwareInterface>hardware_interface/EffortJointInterface</hardwareInterface>
            <mechanicalReduction>1</mechanicalReduction>
        </actuator>
    </transmission>
    <transmission name="trans_finger_joint2">
        <type>transmission_interface/SimpleTransmission</type>
        <joint name="finger_joint2">
            <hardwareInterface>hardware_interface/EffortJointInterface</hardwareInterface>
        </joint>
        <actuator name="finger_joint2_motor">
            <hardwareInterface>hardware_interface/EffortJointInterface</hardwareInterface>
            <mechanicalReduction>1</mechanicalReduction>
        </actuator>
    </transmission>
    <gazebo>
        <plugin name="gazebo_ros_control" filename="libgazebo_ros_control.so">
            <robotNamespace>/</robotNamespace>
        </plugin>
    </gazebo>
</robot>
